[uWSGI] getting INI configuration from /etc/init.d/uwsgi.ini
*** Starting uWSGI 2.0.19.1 (64bit) on [Wed Sep 23 19:27:50 2020] ***
compiled with version: 9.3.0 on 24 September 2020 01:31:51
os: Linux-4.4.0-18362-Microsoft #1049-Microsoft Thu Aug 14 12:01:00 PST 2020
nodename: DESKTOP-8BRLKPO
machine: x86_64
clock source: unix
detected number of CPU cores: 4
current working directory: /home/ooo/kindofparadox
detected binary path: /home/ooo/bin/uwsgi
!!! no internal routing support, rebuild with pcre support !!!
chdir() to /home/ooo/kindofparadox
your processes number limit is 7823
your memory page size is 4096 bytes
detected max file descriptor number: 65536
lock engine: pthread robust mutexes
thunder lock: disabled (you can enable it with --thunder-lock)
uwsgi socket 0 bound to UNIX address /tmp/uwsgi.sock fd 3
Python version: 3.8.2 (default, Jul 16 2020, 14:00:26)  [GCC 9.3.0]
*** Python threads support is disabled. You can enable it with --enable-threads ***
Python main interpreter initialized at 0x7ffff3353e90
your server socket listen backlog is limited to 100 connections
your mercy for graceful operations on workers is 60 seconds
mapped 364520 bytes (355 KB) for 4 cores
*** Operational MODE: preforking ***
WSGI app 0 (mountpoint='') ready in 5 seconds on interpreter 0x7ffff3353e90 pid: 306 (default app)
*** uWSGI is running in multiple interpreter mode ***
spawned uWSGI master process (pid: 306)
spawned uWSGI worker 1 (pid: 310, cores: 1)
spawned uWSGI worker 2 (pid: 311, cores: 1)
spawned uWSGI worker 3 (pid: 312, cores: 1)
spawned uWSGI worker 4 (pid: 313, cores: 1)
Traceback (most recent call last):
  File "/home/ooo/lib/python3.8/site-packages/channels/routing.py", line 29, in get_default_application
    module = importlib.import_module(path)
  File "/usr/lib/python3.8/importlib/__init__.py", line 127, in import_module
    return _bootstrap._gcd_import(name[level:], package, level)
  File "<frozen importlib._bootstrap>", line 1014, in _gcd_import
  File "<frozen importlib._bootstrap>", line 991, in _find_and_load
  File "<frozen importlib._bootstrap>", line 975, in _find_and_load_unlocked
  File "<frozen importlib._bootstrap>", line 671, in _load_unlocked
  File "<frozen importlib._bootstrap_external>", line 783, in exec_module
  File "<frozen importlib._bootstrap>", line 219, in _call_with_frames_removed
  File "./kindofparadox/routing.py", line 4, in <module>
    import chat.routing
ModuleNotFoundError: No module named 'chat.routing'

During handling of the above exception, another exception occurred:

Traceback (most recent call last):
  File "/home/ooo/bin/uvicorn", line 8, in <module>
    sys.exit(main())
  File "/home/ooo/lib/python3.8/site-packages/click/core.py", line 829, in __call__
    return self.main(*args, **kwargs)
  File "/home/ooo/lib/python3.8/site-packages/click/core.py", line 782, in main
    rv = self.invoke(ctx)
  File "/home/ooo/lib/python3.8/site-packages/click/core.py", line 1066, in invoke
    return ctx.invoke(self.callback, **ctx.params)
  File "/home/ooo/lib/python3.8/site-packages/click/core.py", line 610, in invoke
    return callback(*args, **kwargs)
  File "/home/ooo/lib/python3.8/site-packages/uvicorn/main.py", line 339, in main
    run(**kwargs)
  File "/home/ooo/lib/python3.8/site-packages/uvicorn/main.py", line 362, in run
    server.run()
  File "/home/ooo/lib/python3.8/site-packages/uvicorn/main.py", line 390, in run
    loop.run_until_complete(self.serve(sockets=sockets))
  File "uvloop/loop.pyx", line 1456, in uvloop.loop.Loop.run_until_complete
  File "/home/ooo/lib/python3.8/site-packages/uvicorn/main.py", line 397, in serve
    config.load()
  File "/home/ooo/lib/python3.8/site-packages/uvicorn/config.py", line 278, in load
    self.loaded_app = import_from_string(self.app)
  File "/home/ooo/lib/python3.8/site-packages/uvicorn/importer.py", line 20, in import_from_string
    module = importlib.import_module(module_str)
  File "/usr/lib/python3.8/importlib/__init__.py", line 127, in import_module
    return _bootstrap._gcd_import(name[level:], package, level)
  File "<frozen importlib._bootstrap>", line 1014, in _gcd_import
  File "<frozen importlib._bootstrap>", line 991, in _find_and_load
  File "<frozen importlib._bootstrap>", line 975, in _find_and_load_unlocked
  File "<frozen importlib._bootstrap>", line 671, in _load_unlocked
  File "<frozen importlib._bootstrap_external>", line 783, in exec_module
  File "<frozen importlib._bootstrap>", line 219, in _call_with_frames_removed
  File "./kindofparadox/asgi.py", line 19, in <module>
    application = get_default_application()
  File "/home/ooo/lib/python3.8/site-packages/channels/routing.py", line 31, in get_default_application
    raise ImproperlyConfigured("Cannot import ASGI_APPLICATION module %r" % path)
django.core.exceptions.ImproperlyConfigured: Cannot import ASGI_APPLICATION module 'kindofparadox.routing'
Not Found: /chat/
[pid: 311|app: 0|req: 1/1] 127.0.0.1 () {48 vars in 848 bytes} [Thu Sep 24 02:28:20 2020] GET /chat/ => generated 1956 bytes in 120 msecs (HTTP/1.1 404) 5 headers in 159 bytes (1 switches on core 0)
Not Found: /chat/
[pid: 311|app: 0|req: 2/2] 127.0.0.1 () {50 vars in 879 bytes} [Thu Sep 24 02:29:17 2020] GET /chat/ => generated 1956 bytes in 4 msecs (HTTP/1.1 404) 5 headers in 159 bytes (1 switches on core 0)
Internal Server Error: /chat/
Traceback (most recent call last):
  File "/home/ooo/lib/python3.8/site-packages/django/core/handlers/exception.py", line 47, in inner
    response = get_response(request)
  File "/home/ooo/lib/python3.8/site-packages/django/core/handlers/base.py", line 165, in _get_response
    callback, callback_args, callback_kwargs = self.resolve_request(request)
  File "/home/ooo/lib/python3.8/site-packages/django/core/handlers/base.py", line 288, in resolve_request
    resolver_match = resolver.resolve(request.path_info)
  File "/home/ooo/lib/python3.8/site-packages/django/urls/resolvers.py", line 545, in resolve
    for pattern in self.url_patterns:
  File "/home/ooo/lib/python3.8/site-packages/django/utils/functional.py", line 48, in __get__
    res = instance.__dict__[self.name] = self.func(instance)
  File "/home/ooo/lib/python3.8/site-packages/django/urls/resolvers.py", line 589, in url_patterns
    patterns = getattr(self.urlconf_module, "urlpatterns", self.urlconf_module)
  File "/home/ooo/lib/python3.8/site-packages/django/utils/functional.py", line 48, in __get__
    res = instance.__dict__[self.name] = self.func(instance)
  File "/home/ooo/lib/python3.8/site-packages/django/urls/resolvers.py", line 582, in urlconf_module
    return import_module(self.urlconf_name)
  File "/usr/lib/python3.8/importlib/__init__.py", line 127, in import_module
    return _bootstrap._gcd_import(name[level:], package, level)
  File "<frozen importlib._bootstrap>", line 1014, in _gcd_import
  File "<frozen importlib._bootstrap>", line 991, in _find_and_load
  File "<frozen importlib._bootstrap>", line 975, in _find_and_load_unlocked
  File "<frozen importlib._bootstrap>", line 671, in _load_unlocked
  File "<frozen importlib._bootstrap_external>", line 783, in exec_module
  File "<frozen importlib._bootstrap>", line 219, in _call_with_frames_removed
  File "./kindofparadox/urls.py", line 22, in <module>
    path('chat/', include('chat.urls')),
  File "/home/ooo/lib/python3.8/site-packages/django/urls/conf.py", line 34, in include
    urlconf_module = import_module(urlconf_module)
  File "/usr/lib/python3.8/importlib/__init__.py", line 127, in import_module
    return _bootstrap._gcd_import(name[level:], package, level)
  File "<frozen importlib._bootstrap>", line 1014, in _gcd_import
  File "<frozen importlib._bootstrap>", line 991, in _find_and_load
  File "<frozen importlib._bootstrap>", line 973, in _find_and_load_unlocked
ModuleNotFoundError: No module named 'chat.urls'
[pid: 310|app: 0|req: 1/3] 127.0.0.1 () {50 vars in 879 bytes} [Thu Sep 24 02:29:19 2020] GET /chat/ => generated 121046 bytes in 137 msecs (HTTP/1.1 500) 6 headers in 187 bytes (1 switches on core 0)
[pid: 310|app: 0|req: 2/4] 127.0.0.1 () {50 vars in 879 bytes} [Thu Sep 24 02:31:36 2020] GET /chat/ => generated 870 bytes in 129 msecs (HTTP/1.1 200) 5 headers in 166 bytes (1 switches on core 0)
[pid: 310|app: 0|req: 3/5] 127.0.0.1 () {50 vars in 901 bytes} [Thu Sep 24 02:31:40 2020] GET /chat/bla/ => generated 1658 bytes in 33 msecs (HTTP/1.1 200) 5 headers in 167 bytes (1 switches on core 0)
[uWSGI] getting INI configuration from /etc/init.d/uwsgi.ini
*** Starting uWSGI 2.0.19.1 (64bit) on [Wed Sep 23 19:42:12 2020] ***
compiled with version: 9.3.0 on 24 September 2020 01:31:51
os: Linux-4.4.0-18362-Microsoft #1049-Microsoft Thu Aug 14 12:01:00 PST 2020
nodename: DESKTOP-8BRLKPO
machine: x86_64
clock source: unix
detected number of CPU cores: 4
current working directory: /home/ooo/kindofparadox
detected binary path: /home/ooo/bin/uwsgi
!!! no internal routing support, rebuild with pcre support !!!
chdir() to /home/ooo/kindofparadox
your processes number limit is 7823
your memory page size is 4096 bytes
detected max file descriptor number: 1024
lock engine: pthread robust mutexes
thunder lock: disabled (you can enable it with --thunder-lock)
uwsgi socket 0 bound to UNIX address /tmp/uwsgi.sock fd 3
Python version: 3.8.2 (default, Jul 16 2020, 14:00:26)  [GCC 9.3.0]
*** Python threads support is disabled. You can enable it with --enable-threads ***
Python main interpreter initialized at 0x7ffff8501a00
your server socket listen backlog is limited to 100 connections
your mercy for graceful operations on workers is 60 seconds
mapped 364520 bytes (355 KB) for 4 cores
*** Operational MODE: preforking ***
INFO:     Started server process [166]
INFO:     Waiting for application startup.
TRACE:    ASGI [1] Started scope={'type': 'lifespan'}
TRACE:    ASGI [1] Raised exception
INFO:     ASGI 'lifespan' protocol appears unsupported.
INFO:     Application startup complete.
INFO:     Uvicorn running on unix socket /tmp/uvicorn.sock (Press CTRL+C to quit)
WSGI app 0 (mountpoint='') ready in 1 seconds on interpreter 0x7ffff8501a00 pid: 167 (default app)
*** uWSGI is running in multiple interpreter mode ***
spawned uWSGI master process (pid: 167)
spawned uWSGI worker 1 (pid: 171, cores: 1)
spawned uWSGI worker 2 (pid: 172, cores: 1)
spawned uWSGI worker 3 (pid: 173, cores: 1)
spawned uWSGI worker 4 (pid: 174, cores: 1)
[pid: 171|app: 0|req: 1/1] 127.0.0.1 () {50 vars in 879 bytes} [Thu Sep 24 02:42:30 2020] GET /chat/ => generated 870 bytes in 30 msecs (HTTP/1.1 200) 5 headers in 166 bytes (1 switches on core 0)
[pid: 171|app: 0|req: 2/2] 127.0.0.1 () {50 vars in 901 bytes} [Thu Sep 24 02:42:35 2020] GET /chat/eff/ => generated 1658 bytes in 14 msecs (HTTP/1.1 200) 5 headers in 167 bytes (1 switches on core 0)
TRACE:    Connection made
TRACE:    127.0.0.1:0 - ASGI [2] Started scope={'type': 'websocket', 'asgi': {'version': '2.0', 'spec_version': '2.1'}, 'scheme': 'http', 'server': None, 'client': ('127.0.0.1', 0), 'root_path': '', 'path': '/ws/chat/eff/', 'raw_path': '/ws/chat/eff/', 'query_string': b'', 'headers': '<...>', 'subprotocols': []}
TRACE:    127.0.0.1:0 - ASGI [2] Receive {'type': 'websocket.connect'}
TRACE:    127.0.0.1:0 - ASGI [2] Send {'type': 'websocket.accept', 'subprotocol': None}
INFO:     ('127.0.0.1', 0) - "WebSocket /ws/chat/eff/" [accepted]
TRACE:    127.0.0.1:0 - ASGI [2] Receive {'type': 'websocket.receive', 'text': '<17 chars>'}
TRACE:    127.0.0.1:0 - ASGI [2] Send {'type': 'websocket.send', 'text': '<18 chars>'}
TRACE:    127.0.0.1:0 - ASGI [2] Receive {'type': 'websocket.receive', 'text': '<16 chars>'}
TRACE:    127.0.0.1:0 - ASGI [2] Send {'type': 'websocket.send', 'text': '<17 chars>'}
TRACE:    127.0.0.1:0 - ASGI [2] Receive {'type': 'websocket.receive', 'text': '<16 chars>'}
TRACE:    127.0.0.1:0 - ASGI [2] Send {'type': 'websocket.send', 'text': '<17 chars>'}
